#VRML_SIM R2022a utf8
WorldInfo {
  info [
    "Demo to show a bug in the controller robot binding"
  ]
  title "Gantry Robot"
  CFM 0.0001
  ERP 0.6
  basicTimeStep 4
  lineScale 0.5
}
Viewpoint {
  orientation -0.3941642647548964 0.3905770450617365 0.8319159237934289 1.4774971218493598
  position -5.463012800773023 -12.720471973088355 12.759681361703816
}
TexturedBackground {
}
TexturedBackgroundLight {
}
Floor {
  size 100 100
  appearance PBRAppearance {
    baseColorMap ImageTexture {
      url [
        "https://raw.githubusercontent.com/cyberbotics/webots/R2022a/projects/default/worlds/textures/grid.png"
      ]
    }
    roughness 1
    metalness 0
  }
}
DEF RAIL1 Solid {
  translation 0 -0.532 0.01
  children [
    DEF RAIL_SHAPE Shape {
      appearance DEF RAIL_APPEARANCE PBRAppearance {
        roughness 1
        metalness 0
      }
      geometry Box {
        size 80 0.02 0.02
      }
    }
  ]
  name "rail1"
  boundingObject USE RAIL_SHAPE
  locked TRUE
}
DEF RAIL2 Solid {
  translation 0 -0.468 0.01
  children [
    USE RAIL_SHAPE
  ]
  name "rail2"
  boundingObject USE RAIL_SHAPE
  locked TRUE
}
DEF RAIL3 Solid {
  translation 0 0.468 0.01
  children [
    USE RAIL_SHAPE
  ]
  name "rail3"
  boundingObject USE RAIL_SHAPE
  locked TRUE
}
DEF RAIL4 Solid {
  translation 0 0.532 0.01
  children [
    USE RAIL_SHAPE
  ]
  name "rail4"
  boundingObject USE RAIL_SHAPE
  locked TRUE
}
DEF GANTRY Robot {
  translation 0 0 0.98
  children [
    DEF PILLARS_GROUP Group {
      children [
        DEF BRIDGE_TRANS Transform {
          translation 0 0 0.11
          children [
            Shape {
              appearance DEF YELLOW_APPEARANCE PBRAppearance {
                baseColor 1 1 0
                roughness 1
                metalness 0
              }
              geometry Box {
                size 0.2 2 0.12
              }
            }
          ]
        }
        DEF PILLAR1_TRANS Transform {
          translation 0.4 -0.5 -0.44
          children [
            DEF PILLAR_SHAPE Shape {
              appearance USE YELLOW_APPEARANCE
              geometry Box {
                size 0.1 0.1 1
              }
            }
          ]
        }
        DEF PILLAR2_TRANS Transform {
          translation 0.4 0.5 -0.44
          children [
            USE PILLAR_SHAPE
          ]
        }
        DEF PILLAR3_TRANS Transform {
          translation -0.4 -0.5 -0.44
          children [
            USE PILLAR_SHAPE
          ]
        }
        DEF PILLAR4_TRANS Transform {
          translation -0.4 0.5 -0.44
          children [
            USE PILLAR_SHAPE
          ]
        }
        DEF TRANSVERSE1 Transform {
          translation 0 0.5 0.11
          children [
            DEF TRANSVERSE_SHAPE Shape {
              appearance USE YELLOW_APPEARANCE
              geometry Box {
                size 0.9 0.1 0.1
              }
            }
          ]
        }
        DEF TRANSVERSE2 Transform {
          translation 0 -0.5 0.11
          children [
            USE TRANSVERSE_SHAPE
          ]
        }
      ]
    }
    DEF WHEEL1_HINGE_JOINT HingeJoint {
      jointParameters HingeJointParameters {
        axis 0 -1 0
        anchor 0.4 -0.5 -0.9
      }
      device [
        RotationalMotor {
          name "wheel1_motor"
        }
      ]
      endPoint Solid {
        translation 0.4 -0.5 -0.9
        rotation 0 -1 0 0
        children [
          DEF WHEEL1_TRANS Transform {
            rotation -1 0 0 1.5708
            children [
              DEF WHEEL_SHAPE Shape {
                appearance DEF WHEEL_APPEARANCE PBRAppearance {
                  baseColor 0 0 0
                  roughness 1
                  metalness 0
                }
                geometry Cylinder {
                  height 0.04
                  radius 0.08
                }
              }
            ]
          }
        ]
        name "wheel1"
        boundingObject USE WHEEL1_TRANS
        physics DEF WHEEL_PHYSICS Physics {
        }
      }
    }
    DEF WHEEL2_HINGE_JOINT HingeJoint {
      jointParameters HingeJointParameters {
        axis 0 -1 0
        anchor 0.4 0.5 -0.9
      }
      device [
        RotationalMotor {
          name "wheel2_motor"
        }
      ]
      endPoint Solid {
        translation 0.4 0.5 -0.9
        rotation 0 -1 0 0
        children [
          DEF WHEEL2_TRANS Transform {
            rotation -1 0 0 1.5708
            children [
              USE WHEEL_SHAPE
            ]
          }
        ]
        name "wheel2"
        boundingObject USE WHEEL2_TRANS
        physics USE WHEEL_PHYSICS
      }
    }
    DEF WHEEL3_HINGE_JOINT HingeJoint {
      jointParameters HingeJointParameters {
        axis 0 -1 0
        anchor -0.4 -0.5 -0.9
      }
      device [
        RotationalMotor {
          name "wheel3_motor"
        }
      ]
      endPoint Solid {
        translation -0.4 -0.5 -0.9
        rotation 0 -1 0 0
        children [
          DEF WHEEL3_TRANS Transform {
            rotation -1 0 0 1.5708
            children [
              USE WHEEL_SHAPE
            ]
          }
        ]
        name "wheel3"
        boundingObject USE WHEEL3_TRANS
        physics USE WHEEL_PHYSICS
      }
    }
    DEF WHEEL4_HINGE_JOINT HingeJoint {
      jointParameters HingeJointParameters {
        axis 0 -1 0
        anchor -0.4 0.5 -0.9
      }
      device [
        RotationalMotor {
          name "wheel4_motor"
        }
      ]
      endPoint Solid {
        translation -0.4 0.5 -0.9
        rotation 0 -1 0 0
        children [
          DEF WHEEL4_TRANS Transform {
            rotation -1 0 0 1.5708
            children [
              USE WHEEL_SHAPE
            ]
          }
        ]
        name "wheel4"
        boundingObject USE WHEEL4_TRANS
        physics USE WHEEL_PHYSICS
      }
    }
    DEF BRIDGE_SLIDER_JOINT SliderJoint {
      jointParameters JointParameters {
        axis 0 -1 0
        minStop -0.9
        maxStop 0.9
      }
      device [
        LinearMotor {
          name "bridge_motor"
          maxVelocity 1
          minPosition -0.9
          maxPosition 0.9
          maxForce 100
        }
      ]
      endPoint Solid {
        rotation 0 0 1 1.5708
        children [
          GPS {
            name "bridge_motor_gps"
          }
          DEF TURRET_HINGE_JOINT HingeJoint {
            jointParameters HingeJointParameters {
              axis 0 0 1
              anchor 0 0 0.11
            }
            device [
              RotationalMotor {
                name "turret_motor"
                maxVelocity 3.14
                maxTorque 100
              }
            ]
            endPoint Solid {
              translation 0 0 0.11
              rotation 0 0 1 1.5708
              children [
                DEF TURRET_SHAPE Shape {
                  appearance USE WHEEL_APPEARANCE
                  geometry Cylinder {
                    height 0.16
                    radius 0.08
                  }
                }
                DEF LIFT_SLIDER_JOINT SliderJoint {
                  jointParameters JointParameters {
                    axis 0 0 -1
                  }
                  device [
                    LinearMotor {
                      name "lift_motor"
                      maxVelocity 1
                      maxPosition 0.73
                      maxForce 400
                    }
                  ]
                  endPoint Solid {
                    translation 0 0 0.36
                    rotation 0 -1 0 1.5708
                    children [
                      DEF PISTON_GROUP Group {
                        children [
                          Transform {
                            translation -0.5 0 0
                            children [
                              Shape {
                                appearance USE RAIL_APPEARANCE
                                geometry Box {
                                  size 0.04 0.2 0.4
                                }
                              }
                            ]
                          }
                          Transform {
                            rotation 0 -1 0 1.5708
                            children [
                              Shape {
                                appearance USE RAIL_APPEARANCE
                                geometry Cylinder {
                                  height 1
                                  radius 0.05
                                }
                              }
                            ]
                          }
                        ]
                      }
                      DEF GRIPPER_SLIDER_JOINT1 SliderJoint {
                        jointParameters JointParameters {
                        }
                        device [
                          LinearMotor {
                            name "grip_motor1"
                            maxPosition 0.18
                            maxForce 200
                          }
                        ]
                        endPoint Solid {
                          translation -0.6 0 -0.19
                          rotation 0 -1 0 -1.5708
                          children [
                            DEF GRIPPER_SHAPE Shape {
                              appearance USE RAIL_APPEARANCE
                              geometry Box {
                                size 0.02 0.2 0.16
                              }
                            }
                          ]
                          name "grip1"
                          boundingObject USE GRIPPER_SHAPE
                          physics Physics {
                          }
                        }
                      }
                      DEF GRIPPER_SLIDER_JOINT2 SliderJoint {
                        jointParameters JointParameters {
                          axis 0 0 -1
                        }
                        device [
                          LinearMotor {
                            name "grip_motor2"
                            maxPosition 0.18
                            maxForce 200
                          }
                        ]
                        endPoint Solid {
                          translation -0.6 0 0.19
                          rotation 0 -1 0 1.5708
                          children [
                            USE GRIPPER_SHAPE
                          ]
                          name "grip2"
                          boundingObject USE GRIPPER_SHAPE
                          physics Physics {
                          }
                        }
                      }
                    ]
                    boundingObject USE PISTON_GROUP
                    physics Physics {
                    }
                  }
                }
              ]
              boundingObject USE TURRET_SHAPE
              physics Physics {
              }
            }
          }
        ]
        boundingObject Box {
          size 0.1 0.1 0.1
        }
        physics Physics {
        }
      }
    }
  ]
  name "gantry"
  controller "<extern>"
  boundingObject USE PILLARS_GROUP
  physics Physics {
  }
}

Robot {
  translation 0.9 0.9 0.12
  scale 4 4 4
  children [
    HingeJoint {
      jointParameters HingeJointParameters {
        axis 0 1 0
        anchor 0 0 0.025
      }
      device [
        RotationalMotor {
          name "left_wheel_motor_2"
        }
      ]
      endPoint Solid {
        translation 0.0 0.045 0.025
        children [
          DEF WHEEL Transform {
            rotation 1 0 0 1.5707996938995747
            children [
              Shape {
                appearance PBRAppearance {
                  baseColor 1 0 0
                  roughness 1
                  metalness 0
                }
                geometry Cylinder {
                  height 0.01
                  radius 0.025
                }
              }
            ]
          }
        ]
        name "left_wheel_2"
        boundingObject USE WHEEL
        physics Physics {
        }
      }
    }
    HingeJoint {
      jointParameters HingeJointParameters {
        axis 0 1 0
        anchor 0 0 0.025
      }
      device [
        RotationalMotor {
          name "right_wheel_motor_2"
        }
      ]
      endPoint Solid {
        translation 0 -0.045 0.025
        children [
          USE WHEEL
        ]
        name "right wheel 2"
        boundingObject USE WHEEL
        physics Physics {
        }
      }
    }
    Transform {
      translation 0 0 0.0415
      children [
        Shape {
          appearance PBRAppearance {
            baseColor 0 0 1
            roughness 1
            metalness 0
          }
          geometry DEF BODY Cylinder {
            height 0.08
            radius 0.045
          }
        }
      ]
    }
    DistanceSensor {
      translation 0.042 0.02 0.063
      rotation 0 0 1 0.5236003061004253
      children [
        DEF SENSOR Transform {
          rotation 0 1 0 1.5708
          children [
            Shape {
              appearance PBRAppearance {
                baseColor 1 1 0
                roughness 1
                metalness 0
              }
              geometry Cylinder {
                height 0.004
                radius 0.008
              }
            }
          ]
        }
      ]
      name "ds02"
      lookupTable [
        0 1020 0
        0.05 1020 0
        0.15 0 0
      ]
      numberOfRays 2
      aperture 1
    }
    DistanceSensor {
      translation 0.042 -0.02 0.063
      rotation 0 0 1 -0.5235996938995747
      children [
        USE SENSOR
      ]
      name "ds12"
      lookupTable [
        0 1020 0
        0.05 1020 0
        0.15 0 0
      ]
      numberOfRays 2
      aperture 1
    }
  ]
  boundingObject Transform {
    translation 0 0 0.0415
    children [
      USE BODY
    ]
  }
  physics Physics {
  }
  controller "<extern>"
  name "my_simple_robot2"
}

